Workbook

Sheet 中间结果
A1: ID | B1: OPER_TYPE | C1: DIP_CODE | D1: `YEAR` | E1: WEIGHT_SCORE | F1: SERIOUS_COEF | G1: ALLOCATE_WEIGHT_SCORE | H1: DIP_AVG_FEE | I1: REGION_AVE_VAL | J1: THIRD_DIP_COST | K1: AVG_IPT_DAYS | L1: DISCUSS_FLAG | M1: UPLMT_REDC_MAG | N1: WEIGHT | O1: REMARK | P1: TASK_ID | Q1: CV | R1: BILL_COUNT | S1: INVERT_FLAG | T1: THIRD_DIP_CODE
A2: 1.8761743e+18 | B2: 新增 | C2: G45.9:88.4101 | D2: 2024 | E2: 1332.0802 | F2: 1 | G2: 1332.0802 | H2: 7617.0389 | I2: 5718.1535 | J2: 7617.0389 | K2: 9.046312 | L2: 0 | M2: 3 | N2: 1.33208 | P2: 1.8761734e+18 | Q2: 0.253212 | R2: 151 | T2: G45.9:88.4101
A3: 1.8761743e+18 | B3: 新增 | C3: M12:SS | D3: 2024 | E3: 1934.1243 | F3: 1 | G3: 1934.1243 | H3: 11059.619 | I3: 5718.1535 | J3: 11059.619 | K3: 9.020833 | L3: 0 | M3: 3 | N3: 1.934124 | P3: 1.8761734e+18 | Q3: 0.437582 | R3: 35 | T3: M12:SS
A4: 1.8761743e+18 | B4: 新增 | C4: E07.9:06.3102 | D4: 2024 | E4: 2346.8967 | F4: 1 | G4: 2346.8967 | H4: 13419.915 | I4: 5718.1535 | J4: 13419.915 | K4: 3.215686 | L4: 0 | M4: 3 | N4: 2.346897 | P4: 1.8761734e+18 | Q4: 0.216329 | R4: 65 | T4: E07.9:06.3102
A5: 1.8761743e+18 | B5: 新增 | C5: E07.9:06.3100 | D5: 2024 | E5: 2255.3253 | F5: 1 | G5: 2255.3253 | H5: 12896.296 | I5: 5718.1535 | J5: 12896.296 | K5: 8.22807 | L5: 0 | M5: 3 | N5: 2.255325 | P5: 1.8761734e+18 | Q5: 0.363883 | R5: 41 | T5: E07.9:06.3100
A6: 1.8761743e+18 | B6: 新增 | C6: N18.5:38.9502_39.9500 | D6: 2024 | E6: 2105.3322 | F6: 1 | G6: 2105.3322 | H6: 12038.613 | I6: 5718.1535 | J6: 12038.613 | K6: 11.94429 | L6: 0 | M6: 3 | N6: 2.105332 | P6: 1.8761734e+18 | Q6: 0.377933 | R6: 89 | T6: N18.5:38.9502_39.9500
A7: 1.8761743e+18 | B7: 新增 | C7: M81.9 | D7: 2024 | E7: 498.5732 | F7: 1 | G7: 498.5732 | H7: 2850.9181 | I7: 5718.1535 | J7: 2850.9181 | K7: 6.112219 | L7: 0 | M7: 3 | N7: 0.498573 | P7: 1.8761734e+18 | Q7: 0.42948 | R7: 709 | T7: M81.9
A8: 1.8761743e+18 | B8: 新增 | C8: M81.8 | D8: 2024 | E8: 450.19848 | F8: 1 | G8: 450.19848 | H8: 2574.304 | I8: 5718.1535 | J8: 2574.304 | K8: 4.381166 | L8: 0 | M8: 3 | N8: 0.450198 | P8: 1.8761734e+18 | Q8: 0.311287 | R8: 154 | T8: M81.8
A9: 1.8761743e+18 | B9: 新增 | C9: R40.2 | D9: 2024 | E9: 1289.0704 | F9: 1 | G9: 1289.0704 | H9: 7371.1026 | I9: 5718.1535 | J9: 7371.1026 | K9: 7.263252 | L9: 0 | M9: 3 | N9: 1.28907 | P9: 1.8761734e+18 | Q9: 0.952035 | R9: 804 | T9: R40.2
A10: 1.8761743e+18 | B10: 新增 | C10: R40.1 | D10: 2024 | E10: 1442.4374 | F10: 1 | G10: 1442.4374 | H10: 8248.0782 | I10: 5718.1535 | J10: 8248.0782 | K10: 6.527027 | L10: 0 | M10: 3 | N10: 1.442437 | P10: 1.8761734e+18 | Q10: 0.879467 | R10: 30 | T10: R40.1
A11: 1.8761743e+18 | B11: 新增 | C11: I21.0:36.0700_00.2400x001+00.6600x004 | D11: 2024 | E11: 7742.0358 | F11: 1 | G11: 7742.0358 | H11: 44270.149 | I11: 5718.1535 | J11: 44270.149 | K11: 11.886831 | L11: 0 | M11: 3 | N11: 7.742036 | P11: 1.8761734e+18 | Q11: 0.307185 | R11: 136 | T11: I21.0:36.0700_00.2400x001+00.6600x004
A12: 1.8761743e+18 | B12: 新增 | C12: I20.0:00.6601 | D12: 2024 | E12: 4691.1155 | F12: 1 | G12: 4691.1155 | H12: 26824.518 | I12: 5718.1535 | J12: 26824.518 | K12: 7.39928 | L12: 0 | M12: 3 | N12: 4.691115 | P12: 1.8761734e+18 | Q12: 0.2427 | R12: 913 | T12: I20.0:00.6601
A13: 1.8761743e+18 | B13: 新增 | C13: C34.9:33.2702 | D13: 2024 | E13: 2538.0161 | F13: 1 | G13: 2538.0161 | H13: 14512.765 | I13: 5718.1535 | J13: 14512.765 | K13: 10.849315 | L13: 0 | M13: 3 | N13: 2.538016 | P13: 1.8761734e+18 | Q13: 0.365338 | R13: 24 | T13: C34.9:33.2702
... A4449: 1.8761743e+18 | B4449: 新增 | C4449: F80.9 | D4449: 2024 | E4449: 1137.056 | F4449: 1 | G4449: 1137.056 | H4449: 6501.8607 | I4449: 5718.1535 | J4449: 6501.8607 | K4449: 24.494862 | L4449: 0 | M4449: 3 | N4449: 1.137056 | P4449: 1.8761734e+18 | Q4449: 0.405385 | R4449: 921 | T4449: F80.9
A4450: 1.8761743e+18 | B4450: 新增 | C4450: CP01:SS | D4450: 2024 | E4450: 1000 | F4450: 1 | G4450: 1000 | H4450: 5718.1535 | I4450: 5718.1535 | J4450: 5718.1535 | L4450: 1 | M4450: 3 | N4450: 1 | O4450: 未入组病例的分组 | P4450: 1.8761734e+18 | T4450: CP01:SS
A4451: 1.8761743e+18 | B4451: 新增 | C4451: CP01:ZLXCZ | D4451: 2024 | E4451: 1000 | F4451: 1 | G4451: 1000 | H4451: 5718.1535 | I4451: 5718.1535 | J4451: 5718.1535 | L4451: 1 | M4451: 3 | N4451: 1 | O4451: 未入组病例的分组 | P4451: 1.8761734e+18 | T4451: CP01:ZLXCZ
A4452: 1.8761743e+18 | B4452: 新增 | C4452: CP01:ZDXCZ | D4452: 2024 | E4452: 1000 | F4452: 1 | G4452: 1000 | H4452: 5718.1535 | I4452: 5718.1535 | J4452: 5718.1535 | L4452: 1 | M4452: 3 | N4452: 1 | O4452: 未入组病例的分组 | P4452: 1.8761734e+18 | T4452: CP01:ZDXCZ
A4453: 1.8761743e+18 | B4453: 新增 | C4453: CP01:BSZL | D4453: 2024 | E4453: 1000 | F4453: 1 | G4453: 1000 | H4453: 5718.1535 | I4453: 5718.1535 | J4453: 5718.1535 | L4453: 1 | M4453: 3 | N4453: 1 | O4453: 未入组病例的分组 | P4453: 1.8761734e+18 | T4453: CP01:BSZL
A4454: 1.8761743e+18 | B4454: 新增 | C4454: CP02:SS | D4454: 2024 | E4454: 1000 | F4454: 1 | G4454: 1000 | H4454: 5718.1535 | I4454: 5718.1535 | J4454: 5718.1535 | L4454: 1 | M4454: 3 | N4454: 1 | O4454: 未入组病例的分组 | P4454: 1.8761734e+18 | T4454: CP02:SS
A4455: 1.8761743e+18 | B4455: 新增 | C4455: CP02:ZLXCZ | D4455: 2024 | E4455: 1000 | F4455: 1 | G4455: 1000 | H4455: 5718.1535 | I4455: 5718.1535 | J4455: 5718.1535 | L4455: 1 | M4455: 3 | N4455: 1 | O4455: 未入组病例的分组 | P4455: 1.8761734e+18 | T4455: CP02:ZLXCZ
A4456: 1.8761743e+18 | B4456: 新增 | C4456: CP02:ZDXCZ | D4456: 2024 | E4456: 1000 | F4456: 1 | G4456: 1000 | H4456: 5718.1535 | I4456: 5718.1535 | J4456: 5718.1535 | L4456: 1 | M4456: 3 | N4456: 1 | O4456: 未入组病例的分组 | P4456: 1.8761734e+18 | T4456: CP02:ZDXCZ
A4457: 1.8761743e+18 | B4457: 新增 | C4457: CP02:BSZL | D4457: 2024 | E4457: 1000 | F4457: 1 | G4457: 1000 | H4457: 5718.1535 | I4457: 5718.1535 | J4457: 5718.1535 | L4457: 1 | M4457: 3 | N4457: 1 | O4457: 未入组病例的分组 | P4457: 1.8761734e+18 | T4457: CP02:BSZL
A4458: 1.8761743e+18 | B4458: 新增 | C4458: CP03:SS | D4458: 2024 | E4458: 1000 | F4458: 1 | G4458: 1000 | H4458: 5718.1535 | I4458: 5718.1535 | J4458: 5718.1535 | L4458: 1 | M4458: 3 | N4458: 1 | O4458: 未入组病例的分组 | P4458: 1.8761734e+18 | T4458: CP03:SS
A4459: 1.8761743e+18 | B4459: 新增 | C4459: CP03:ZLXCZ | D4459: 2024 | E4459: 1000 | F4459: 1 | G4459: 1000 | H4459: 5718.1535 | I4459: 5718.1535 | J4459: 5718.1535 | L4459: 1 | M4459: 3 | N4459: 1 | O4459: 未入组病例的分组 | P4459: 1.8761734e+18 | T4459: CP03:ZLXCZ
A4460: 1.8761743e+18 | B4460: 新增 | C4460: CP03:ZDXCZ | D4460: 2024 | E4460: 1000 | F4460: 1 | G4460: 1000 | H4460: 5718.1535 | I4460: 5718.1535 | J4460: 5718.1535 | L4460: 1 | M4460: 3 | N4460: 1 | O4460: 未入组病例的分组 | P4460: 1.8761734e+18 | T4460: CP03:ZDXCZ
A4461: 1.8761743e+18 | B4461: 新增 | C4461: CP03:BSZL | D4461: 2024 | E4461: 1000 | F4461: 1 | G4461: 1000 | H4461: 5718.1535 | I4461: 5718.1535 | J4461: 5718.1535 | L4461: 1 | M4461: 3 | N4461: 1 | O4461: 未入组病例的分组 | P4461: 1.8761734e+18 | T4461: CP03:BSZL
... A4537: 1.8761743e+18 | B4537: 新增 | C4537: CP22:BSZL | D4537: 2024 | E4537: 1000 | F4537: 1 | G4537: 1000 | H4537: 5718.1535 | I4537: 5718.1535 | J4537: 5718.1535 | L4537: 1 | M4537: 3 | N4537: 1 | O4537: 未入组病例的分组 | P4537: 1.8761734e+18 | T4537: CP22:BSZL

Sheet 目录
A1: 序号 | B1: 病种编码 | C1: 病种类型（1.核心病种；2.综合病种） | D1: 主诊断代码 | E1: 主诊断名称 | F1: 主要操作代码 | G1: 主要操作名称 | H1: 其他操作代码 | I1: 其他操作名称 | J1: 病种分值
A2: 1 | B2: A03.9 | C2: 1 | D2: A03.9 | E2: 未特指的细菌性痢疾 | J2: =VLOOKUP(B:B,中间结果!C:T,5,FALSE) -> 385.35787
A3: 2 | B3: A04.9 | C3: 1 | D3: A04.9 | E3: 未特指的细菌性肠道感染 | J3: =VLOOKUP(B:B,中间结果!C:T,5,FALSE) -> 385.17625
A4: 3 | B4: A08.0 | C4: 1 | D4: A08.0 | E4: 轮状病毒性肠炎 | J4: =VLOOKUP(B:B,中间结果!C:T,5,FALSE) -> 246.41526
A5: 4 | B5: A08.4 | C5: 1 | D5: A08.4 | E5: 未特指的病毒性肠道感染 | J5: =VLOOKUP(B:B,中间结果!C:T,5,FALSE) -> 254.31664
A6: 5 | B6: A09.0 | C6: 1 | D6: A09.0 | E6: 其他和未特指传染性病因的胃肠炎和结肠炎 | J6: =VLOOKUP(B:B,中间结果!C:T,5,FALSE) -> 402.82449
A7: 6 | B7: A09.9 | C7: 1 | D7: A09.9 | E7: 未特指病因的胃肠炎和结肠炎 | J7: =VLOOKUP(B:B,中间结果!C:T,5,FALSE) -> 331.60872
A8: 7 | B8: A09.9:44.1300x001 | C8: 1 | D8: A09.9 | E8: 未特指病因的胃肠炎和结肠炎 | F8: 44.1300X001 | G8: 胃镜检查 | J8: =VLOOKUP(B:B,中间结果!C:T,5,FALSE) -> 635.32356
A9: 8 | B9: A09.9:44.1300x001_45.2302 | C9: 1 | D9: A09.9 | E9: 未特指病因的胃肠炎和结肠炎 | F9: 44.1300X001 | G9: 胃镜检查 | H9: 45.2302 | I9: 电子结肠镜检查 | J9: =VLOOKUP(B:B,中间结果!C:T,5,FALSE) -> 676.62353
A10: 9 | B10: A09.9:45.1300x004 | C10: 1 | D10: A09.9 | E10: 未特指病因的胃肠炎和结肠炎 | F10: 45.1300X004 | G10: 胃-十二指肠镜检查 | J10: =VLOOKUP(B:B,中间结果!C:T,5,FALSE) -> 563.14415
A11: 120 | B11: C18.9:17.3900x002 | C11: 1 | D11: C18.9 | E11: 未特指的结肠恶性肿瘤 | F11: 17.3900X002 | G11: 腹腔镜下结肠部分切除术 | J11: =VLOOKUP(B:B,中间结果!C:T,5,FALSE) -> 8202.5401
A12: 114 | B12: C18.2:45.7302 | C12: 1 | D12: C18.2 | E12: 升结肠恶性肿瘤 | F12: 45.7302 | G12: 右半结肠根治性切除术 | J12: =VLOOKUP(B:B,中间结果!C:T,5,FALSE) -> 7791.8003
A13: 12 | B13: A15.0 | C13: 1 | D13: A15.0 | E13: 肺结核，经显微镜下痰检查证实，伴有或不伴有痰培养 | J13: =VLOOKUP(B:B,中间结果!C:T,5,FALSE) -> 1530.3882
A14: 13 | B14: A15.0:33.2302 | C14: 1 | D14: A15.0 | E14: 肺结核，经显微镜下痰检查证实，伴有或不伴有痰培养 | F14: 33.2302 | G14: 电子支气管镜检查 | J14: =VLOOKUP(B:B,中间结果!C:T,5,FALSE) -> 1423.0766
A15: 14 | B15: A15.0:33.2403 | C15: 1 | D15: A15.0 | E15: 肺结核，经显微镜下痰检查证实，伴有或不伴有痰培养 | F15: 33.2403 | G15: 纤维支气管镜检查伴肺泡灌洗术 | J15: =VLOOKUP(B:B,中间结果!C:T,5,FALSE) -> 1619.4624
A16: 15 | B16: A15.0:34.0401 | C16: 1 | D16: A15.0 | E16: 肺结核，经显微镜下痰检查证实，伴有或不伴有痰培养 | F16: 34.0401 | G16: 胸腔闭式引流术 | J16: =VLOOKUP(B:B,中间结果!C:T,5,FALSE) -> 2455.7502
A17: 16 | B17: A15.1 | C17: 1 | D17: A15.1 | E17: 肺结核,仅经痰培养所证实 | J17: =VLOOKUP(B:B,中间结果!C:T,5,FALSE) -> 1287.0967
A18: 17 | B18: A15.2 | C18: 1 | D18: A15.2 | E18: 肺结核，经组织学所证实 | J18: =VLOOKUP(B:B,中间结果!C:T,5,FALSE) -> 1212.3797
A19: 18 | B19: A15.3 | C19: 1 | D19: A15.3 | E19: 肺结核，经未特指的方法所证实 | J19: =VLOOKUP(B:B,中间结果!C:T,5,FALSE) -> 1012.0192
A20: 19 | B20: A16.0 | C20: 1 | D20: A16.0 | E20: 肺结核，细菌学和组织学检查为阴性 | J20: =VLOOKUP(B:B,中间结果!C:T,5,FALSE) -> 1464.2048
A21: 20 | B21: A16.0:33.2403 | C21: 1 | D21: A16.0 | E21: 肺结核，细菌学和组织学检查为阴性 | F21: 33.2403 | G21: 纤维支气管镜检查伴肺泡灌洗术 | J21: =VLOOKUP(B:B,中间结果!C:T,5,FALSE) -> 1203.44
A22: 21 | B22: A16.0:34.0401 | C22: 1 | D22: A16.0 | E22: 肺结核，细菌学和组织学检查为阴性 | F22: 34.0401 | G22: 胸腔闭式引流术 | J22: =VLOOKUP(B:B,中间结果!C:T,5,FALSE) -> 2021.863
A23: 22 | B23: A16.2 | C23: 1 | D23: A16.2 | E23: 肺结核，未提及细菌学或组织学的证实 | J23: =VLOOKUP(B:B,中间结果!C:T,5,FALSE) -> 1241.0246
A24: 23 | B24: A16.2:33.2200x003 | C24: 1 | D24: A16.2 | E24: 肺结核，未提及细菌学或组织学的证实 | F24: 33.2200X003 | G24: 纤维支气管镜检查 | J24: =VLOOKUP(B:B,中间结果!C:T,5,FALSE) -> 915.35367
A25: 24 | B25: A16.2:33.2403 | C25: 1 | D25: A16.2 | E25: 肺结核，未提及细菌学或组织学的证实 | F25: 33.2403 | G25: 纤维支气管镜检查伴肺泡灌洗术 | J25: =VLOOKUP(B:B,中间结果!C:T,5,FALSE) -> 1348.2995
A26: 25 | B26: A16.2:34.0401 | C26: 1 | D26: A16.2 | E26: 肺结核，未提及细菌学或组织学的证实 | F26: 34.0401 | G26: 胸腔闭式引流术 | J26: =VLOOKUP(B:B,中间结果!C:T,5,FALSE) -> 1747.2
A27: 26 | B27: A16.5 | C27: 1 | D27: A16.5 | E27: 结核性胸膜炎，未提及细菌学或组织学的证实 | J27: =VLOOKUP(B:B,中间结果!C:T,5,FALSE) -> 1179.396
A28: 27 | B28: A16.5:34.0401 | C28: 1 | D28: A16.5 | E28: 结核性胸膜炎，未提及细菌学或组织学的证实 | F28: 34.0401 | G28: 胸腔闭式引流术 | J28: =VLOOKUP(B:B,中间结果!C:T,5,FALSE) -> 1589.8057
A29: 28 | B29: A16.5:34.9101 | C29: 1 | D29: A16.5 | E29: 结核性胸膜炎，未提及细菌学或组织学的证实 | F29: 34.9101 | G29: 胸腔穿刺抽液术 | J29: =VLOOKUP(B:B,中间结果!C:T,5,FALSE) -> 1489.3133
A30: 29 | B30: A16.5:34.9103 | C30: 1 | D30: A16.5 | E30: 结核性胸膜炎，未提及细菌学或组织学的证实 | F30: 34.9103 | G30: 超声引导下胸腔穿刺术 | J30: =VLOOKUP(B:B,中间结果!C:T,5,FALSE) -> 1378.2605
A31: 30 | B31: A16.9 | C31: 1 | D31: A16.9 | E31: 未特指的呼吸道结核，未提及细菌学或组织学的证实 | J31: =VLOOKUP(B:B,中间结果!C:T,5,FALSE) -> 762.57948
A32: 31 | B32: A18.0 | C32: 1 | D32: A18.0 | E32: 骨和关节的结核 | J32: =VLOOKUP(B:B,中间结果!C:T,5,FALSE) -> 1168.042
A33: 32 | B33: A18.1 | C33: 1 | D33: A18.1 | E33: 泌尿生殖系统的结核 | J33: =VLOOKUP(B:B,中间结果!C:T,5,FALSE) -> 1022.5112
A34: 33 | B34: A18.2 | C34: 1 | D34: A18.2 | E34: 结核性周围淋巴结病 | J34: =VLOOKUP(B:B,中间结果!C:T,5,FALSE) -> 1233.1418
A35: 34 | B35: A18.3 | C35: 1 | D35: A18.3 | E35: 肠、腹膜和肠系膜淋巴结的结核 | J35: =VLOOKUP(B:B,中间结果!C:T,5,FALSE) -> 1234.7717
A36: 35 | B36: A23.0 | C36: 1 | D36: A23.0 | E36: 马耳他布氏菌病 | J36: =VLOOKUP(B:B,中间结果!C:T,5,FALSE) -> 749.13424
A37: 36 | B37: A23.9 | C37: 1 | D37: A23.9 | E37: 未特指的布氏菌病 | J37: =VLOOKUP(B:B,中间结果!C:T,5,FALSE) -> 923.50664
A38: 37 | B38: A26.0 | C38: 1 | D38: A26.0 | E38: 皮肤类丹毒 | J38: =VLOOKUP(B:B,中间结果!C:T,5,FALSE) -> 552.06539
A39: 38 | B39: A31.0 | C39: 1 | D39: A31.0 | E39: 肺分枝杆菌感染 | J39: =VLOOKUP(B:B,中间结果!C:T,5,FALSE) -> 1523.6644
A40: 39 | B40: A37.9 | C40: 1 | D40: A37.9 | E40: 未特指的百日咳 | J40: =VLOOKUP(B:B,中间结果!C:T,5,FALSE) -> 709.93442
...
